2021-05-02 15:12:56,842 ERROR: Exception on /update_testpoint [POST] [in /home/michael/Projects/InstroCommTool/venv/lib/python3.8/site-packages/flask/app.py:1891
Traceback (most recent call last):
  File "/home/michael/Projects/InstroCommTool/venv/lib/python3.8/site-packages/flask/app.py", line 2447, in wsgi_app
    response = self.full_dispatch_request()
  File "/home/michael/Projects/InstroCommTool/venv/lib/python3.8/site-packages/flask/app.py", line 1952, in full_dispatch_request
    rv = self.handle_user_exception(e)
  File "/home/michael/Projects/InstroCommTool/venv/lib/python3.8/site-packages/flask/app.py", line 1821, in handle_user_exception
    reraise(exc_type, exc_value, tb)
  File "/home/michael/Projects/InstroCommTool/venv/lib/python3.8/site-packages/flask/_compat.py", line 39, in reraise
    raise value
  File "/home/michael/Projects/InstroCommTool/venv/lib/python3.8/site-packages/flask/app.py", line 1950, in full_dispatch_request
    rv = self.dispatch_request()
  File "/home/michael/Projects/InstroCommTool/venv/lib/python3.8/site-packages/flask/app.py", line 1936, in dispatch_request
    return self.view_functions[rule.endpoint](**req.view_args)
  File "/home/michael/Projects/InstroCommTool/app/main/routes.py", line 156, in update_testpoint
    testpoint = Testpoint.query.filter_by(id=id)
NameError: name 'Testpoint' is not defined
2021-05-02 15:13:12,714 INFO: InstroCommTool [in /home/michael/Projects/InstroCommTool/app/__init__.py:83
2021-05-02 15:34:04,763 INFO: InstroCommTool [in /home/michael/Projects/InstroCommTool/app/__init__.py:83
2021-05-02 15:35:43,616 INFO: InstroCommTool [in /home/michael/Projects/InstroCommTool/app/__init__.py:83
2021-05-02 15:37:18,367 INFO: InstroCommTool [in /home/michael/Projects/InstroCommTool/app/__init__.py:83
2021-05-02 15:38:50,968 INFO: InstroCommTool [in /home/michael/Projects/InstroCommTool/app/__init__.py:83
2021-05-02 15:39:09,983 ERROR: Exception on /update_testpoint [POST] [in /home/michael/Projects/InstroCommTool/venv/lib/python3.8/site-packages/flask/app.py:1891
Traceback (most recent call last):
  File "/home/michael/Projects/InstroCommTool/venv/lib/python3.8/site-packages/flask/app.py", line 2447, in wsgi_app
    response = self.full_dispatch_request()
  File "/home/michael/Projects/InstroCommTool/venv/lib/python3.8/site-packages/flask/app.py", line 1952, in full_dispatch_request
    rv = self.handle_user_exception(e)
  File "/home/michael/Projects/InstroCommTool/venv/lib/python3.8/site-packages/flask/app.py", line 1821, in handle_user_exception
    reraise(exc_type, exc_value, tb)
  File "/home/michael/Projects/InstroCommTool/venv/lib/python3.8/site-packages/flask/_compat.py", line 39, in reraise
    raise value
  File "/home/michael/Projects/InstroCommTool/venv/lib/python3.8/site-packages/flask/app.py", line 1950, in full_dispatch_request
    rv = self.dispatch_request()
  File "/home/michael/Projects/InstroCommTool/venv/lib/python3.8/site-packages/flask/app.py", line 1936, in dispatch_request
    return self.view_functions[rule.endpoint](**req.view_args)
  File "/home/michael/Projects/InstroCommTool/app/main/routes.py", line 157, in update_testpoint
    print(testpoint.input_val)
AttributeError: 'BaseQuery' object has no attribute 'input_val'
2021-05-02 15:40:14,109 INFO: InstroCommTool [in /home/michael/Projects/InstroCommTool/app/__init__.py:83
2021-05-02 15:46:08,856 INFO: InstroCommTool [in /home/michael/Projects/InstroCommTool/app/__init__.py:83
2021-05-02 15:46:24,140 ERROR: Exception on /update_testpoint [POST] [in /home/michael/Projects/InstroCommTool/venv/lib/python3.8/site-packages/flask/app.py:1891
Traceback (most recent call last):
  File "/home/michael/Projects/InstroCommTool/venv/lib/python3.8/site-packages/sqlalchemy/engine/base.py", line 1204, in _execute_context
    context = constructor(dialect, self, conn, *args)
  File "/home/michael/Projects/InstroCommTool/venv/lib/python3.8/site-packages/sqlalchemy/engine/default.py", line 854, in _init_compiled
    param.append(processors[key](compiled_params[key]))
ValueError: could not convert string to float: ''

The above exception was the direct cause of the following exception:

Traceback (most recent call last):
  File "/home/michael/Projects/InstroCommTool/venv/lib/python3.8/site-packages/flask/app.py", line 2447, in wsgi_app
    response = self.full_dispatch_request()
  File "/home/michael/Projects/InstroCommTool/venv/lib/python3.8/site-packages/flask/app.py", line 1952, in full_dispatch_request
    rv = self.handle_user_exception(e)
  File "/home/michael/Projects/InstroCommTool/venv/lib/python3.8/site-packages/flask/app.py", line 1821, in handle_user_exception
    reraise(exc_type, exc_value, tb)
  File "/home/michael/Projects/InstroCommTool/venv/lib/python3.8/site-packages/flask/_compat.py", line 39, in reraise
    raise value
  File "/home/michael/Projects/InstroCommTool/venv/lib/python3.8/site-packages/flask/app.py", line 1950, in full_dispatch_request
    rv = self.dispatch_request()
  File "/home/michael/Projects/InstroCommTool/venv/lib/python3.8/site-packages/flask/app.py", line 1936, in dispatch_request
    return self.view_functions[rule.endpoint](**req.view_args)
  File "/home/michael/Projects/InstroCommTool/app/main/routes.py", line 160, in update_testpoint
    db.session.commit()
  File "/home/michael/Projects/InstroCommTool/venv/lib/python3.8/site-packages/sqlalchemy/orm/scoping.py", line 163, in do
    return getattr(self.registry(), name)(*args, **kwargs)
  File "/home/michael/Projects/InstroCommTool/venv/lib/python3.8/site-packages/sqlalchemy/orm/session.py", line 1046, in commit
    self.transaction.commit()
  File "/home/michael/Projects/InstroCommTool/venv/lib/python3.8/site-packages/sqlalchemy/orm/session.py", line 504, in commit
    self._prepare_impl()
  File "/home/michael/Projects/InstroCommTool/venv/lib/python3.8/site-packages/sqlalchemy/orm/session.py", line 483, in _prepare_impl
    self.session.flush()
  File "/home/michael/Projects/InstroCommTool/venv/lib/python3.8/site-packages/sqlalchemy/orm/session.py", line 2540, in flush
    self._flush(objects)
  File "/home/michael/Projects/InstroCommTool/venv/lib/python3.8/site-packages/sqlalchemy/orm/session.py", line 2682, in _flush
    transaction.rollback(_capture_exception=True)
  File "/home/michael/Projects/InstroCommTool/venv/lib/python3.8/site-packages/sqlalchemy/util/langhelpers.py", line 68, in __exit__
    compat.raise_(
  File "/home/michael/Projects/InstroCommTool/venv/lib/python3.8/site-packages/sqlalchemy/util/compat.py", line 182, in raise_
    raise exception
  File "/home/michael/Projects/InstroCommTool/venv/lib/python3.8/site-packages/sqlalchemy/orm/session.py", line 2642, in _flush
    flush_context.execute()
  File "/home/michael/Projects/InstroCommTool/venv/lib/python3.8/site-packages/sqlalchemy/orm/unitofwork.py", line 422, in execute
    rec.execute(self)
  File "/home/michael/Projects/InstroCommTool/venv/lib/python3.8/site-packages/sqlalchemy/orm/unitofwork.py", line 586, in execute
    persistence.save_obj(
  File "/home/michael/Projects/InstroCommTool/venv/lib/python3.8/site-packages/sqlalchemy/orm/persistence.py", line 230, in save_obj
    _emit_update_statements(
  File "/home/michael/Projects/InstroCommTool/venv/lib/python3.8/site-packages/sqlalchemy/orm/persistence.py", line 994, in _emit_update_statements
    c = cached_connections[connection].execute(
  File "/home/michael/Projects/InstroCommTool/venv/lib/python3.8/site-packages/sqlalchemy/engine/base.py", line 1011, in execute
    return meth(self, multiparams, params)
  File "/home/michael/Projects/InstroCommTool/venv/lib/python3.8/site-packages/sqlalchemy/sql/elements.py", line 298, in _execute_on_connection
    return connection._execute_clauseelement(self, multiparams, params)
  File "/home/michael/Projects/InstroCommTool/venv/lib/python3.8/site-packages/sqlalchemy/engine/base.py", line 1124, in _execute_clauseelement
    ret = self._execute_context(
  File "/home/michael/Projects/InstroCommTool/venv/lib/python3.8/site-packages/sqlalchemy/engine/base.py", line 1206, in _execute_context
    self._handle_dbapi_exception(
  File "/home/michael/Projects/InstroCommTool/venv/lib/python3.8/site-packages/sqlalchemy/engine/base.py", line 1510, in _handle_dbapi_exception
    util.raise_(
  File "/home/michael/Projects/InstroCommTool/venv/lib/python3.8/site-packages/sqlalchemy/util/compat.py", line 182, in raise_
    raise exception
  File "/home/michael/Projects/InstroCommTool/venv/lib/python3.8/site-packages/sqlalchemy/engine/base.py", line 1204, in _execute_context
    context = constructor(dialect, self, conn, *args)
  File "/home/michael/Projects/InstroCommTool/venv/lib/python3.8/site-packages/sqlalchemy/engine/default.py", line 854, in _init_compiled
    param.append(processors[key](compiled_params[key]))
sqlalchemy.exc.StatementError: (builtins.ValueError) could not convert string to float: ''
[SQL: UPDATE test_point SET input_val=? WHERE test_point.id = ?]
[parameters: [{'input_val': '', 'test_point_id': 2}]]
2021-05-02 16:22:13,124 INFO: InstroCommTool [in /home/michael/Projects/InstroCommTool/app/__init__.py:83
2021-05-02 16:24:42,077 INFO: InstroCommTool [in /home/michael/Projects/InstroCommTool/app/__init__.py:83
2021-05-02 19:29:41,707 INFO: InstroCommTool [in /home/michael/Projects/InstroCommTool/app/__init__.py:83
2021-05-02 19:32:35,616 INFO: InstroCommTool [in /home/michael/Projects/InstroCommTool/app/__init__.py:83
2021-05-02 19:35:23,811 INFO: InstroCommTool [in /home/michael/Projects/InstroCommTool/app/__init__.py:83
2021-05-02 19:36:05,105 INFO: InstroCommTool [in /home/michael/Projects/InstroCommTool/app/__init__.py:83
