2021-05-01 16:58:58,890 ERROR: Exception on /channel_list [GET] [in /home/michael/Projects/InstroCommTool/venv/lib/python3.8/site-packages/flask/app.py:1891
Traceback (most recent call last):
  File "/home/michael/Projects/InstroCommTool/venv/lib/python3.8/site-packages/flask/app.py", line 2447, in wsgi_app
    response = self.full_dispatch_request()
  File "/home/michael/Projects/InstroCommTool/venv/lib/python3.8/site-packages/flask/app.py", line 1952, in full_dispatch_request
    rv = self.handle_user_exception(e)
  File "/home/michael/Projects/InstroCommTool/venv/lib/python3.8/site-packages/flask/app.py", line 1821, in handle_user_exception
    reraise(exc_type, exc_value, tb)
  File "/home/michael/Projects/InstroCommTool/venv/lib/python3.8/site-packages/flask/_compat.py", line 39, in reraise
    raise value
  File "/home/michael/Projects/InstroCommTool/venv/lib/python3.8/site-packages/flask/app.py", line 1950, in full_dispatch_request
    rv = self.dispatch_request()
  File "/home/michael/Projects/InstroCommTool/venv/lib/python3.8/site-packages/flask/app.py", line 1936, in dispatch_request
    return self.view_functions[rule.endpoint](**req.view_args)
  File "/home/michael/Projects/InstroCommTool/app/main/routes.py", line 143, in channel_list
    return render_template('channel_list.html', title='Channel List', channel_group_form=channel_group_form, units_dict=ENG_UNITS,
  File "/home/michael/Projects/InstroCommTool/venv/lib/python3.8/site-packages/flask/templating.py", line 137, in render_template
    return _render(
  File "/home/michael/Projects/InstroCommTool/venv/lib/python3.8/site-packages/flask/templating.py", line 120, in _render
    rv = template.render(context)
  File "/home/michael/Projects/InstroCommTool/venv/lib/python3.8/site-packages/jinja2/environment.py", line 1090, in render
    self.environment.handle_exception()
  File "/home/michael/Projects/InstroCommTool/venv/lib/python3.8/site-packages/jinja2/environment.py", line 832, in handle_exception
    reraise(*rewrite_traceback_stack(source=source))
  File "/home/michael/Projects/InstroCommTool/venv/lib/python3.8/site-packages/jinja2/_compat.py", line 28, in reraise
    raise value.with_traceback(tb)
  File "/home/michael/Projects/InstroCommTool/app/templates/channel_list.html", line 2, in top-level template code
    {% import 'bootstrap/form.html' as wtf %}
  File "/home/michael/Projects/InstroCommTool/app/templates/base.html", line 43, in top-level template code
    {% block content %}
  File "/home/michael/Projects/InstroCommTool/app/templates/base.html", line 53, in block "content"
    {% block app_content %}{% endblock %}
  File "/home/michael/Projects/InstroCommTool/app/templates/channel_list.html", line 26, in block "app_content"
    {% include '_testpoint.html' %}
  File "/home/michael/Projects/InstroCommTool/venv/lib/python3.8/site-packages/jinja2/environment.py", line 832, in handle_exception
    reraise(*rewrite_traceback_stack(source=source))
  File "/home/michael/Projects/InstroCommTool/venv/lib/python3.8/site-packages/jinja2/_compat.py", line 28, in reraise
    raise value.with_traceback(tb)
  File "/home/michael/Projects/InstroCommTool/app/templates/_testpoint.html", line 26, in template
    {{ testpoint_form.input_val(placeholder=round(testpoint.input_val_nom, 3), class="input-val", data-testpoint="4", value="") }}
jinja2.exceptions.TemplateSyntaxError: invalid syntax for function call expression
2021-05-01 17:05:38,006 INFO: InstroCommTool [in /home/michael/Projects/InstroCommTool/app/__init__.py:83
2021-05-01 17:06:00,122 INFO: InstroCommTool [in /home/michael/Projects/InstroCommTool/app/__init__.py:83
2021-05-01 17:09:52,856 INFO: InstroCommTool [in /home/michael/Projects/InstroCommTool/app/__init__.py:83
2021-05-01 17:11:53,429 INFO: InstroCommTool [in /home/michael/Projects/InstroCommTool/app/__init__.py:83
2021-05-01 17:34:59,028 INFO: InstroCommTool [in /home/michael/Projects/InstroCommTool/app/__init__.py:83
2021-05-01 17:37:17,719 INFO: InstroCommTool [in /home/michael/Projects/InstroCommTool/app/__init__.py:83
2021-05-01 17:37:37,179 INFO: InstroCommTool [in /home/michael/Projects/InstroCommTool/app/__init__.py:83
2021-05-01 17:45:31,017 INFO: InstroCommTool [in /home/michael/Projects/InstroCommTool/app/__init__.py:83
2021-05-01 17:46:36,868 INFO: InstroCommTool [in /home/michael/Projects/InstroCommTool/app/__init__.py:83
2021-05-01 17:56:43,786 INFO: InstroCommTool [in /home/michael/Projects/InstroCommTool/app/__init__.py:83
2021-05-01 17:58:50,940 INFO: InstroCommTool [in /home/michael/Projects/InstroCommTool/app/__init__.py:83
2021-05-01 17:59:03,586 ERROR: Exception on /update_testpoint [POST] [in /home/michael/Projects/InstroCommTool/venv/lib/python3.8/site-packages/flask/app.py:1891
Traceback (most recent call last):
  File "/home/michael/Projects/InstroCommTool/venv/lib/python3.8/site-packages/flask/app.py", line 2447, in wsgi_app
    response = self.full_dispatch_request()
  File "/home/michael/Projects/InstroCommTool/venv/lib/python3.8/site-packages/flask/app.py", line 1952, in full_dispatch_request
    rv = self.handle_user_exception(e)
  File "/home/michael/Projects/InstroCommTool/venv/lib/python3.8/site-packages/flask/app.py", line 1821, in handle_user_exception
    reraise(exc_type, exc_value, tb)
  File "/home/michael/Projects/InstroCommTool/venv/lib/python3.8/site-packages/flask/_compat.py", line 39, in reraise
    raise value
  File "/home/michael/Projects/InstroCommTool/venv/lib/python3.8/site-packages/flask/app.py", line 1950, in full_dispatch_request
    rv = self.dispatch_request()
  File "/home/michael/Projects/InstroCommTool/venv/lib/python3.8/site-packages/flask/app.py", line 1936, in dispatch_request
    return self.view_functions[rule.endpoint](**req.view_args)
  File "/home/michael/Projects/InstroCommTool/app/main/routes.py", line 152, in update_testpoint
    print(f'testpoint_id = {testpoint_id}, new_input_val = {new_input_val}')
NameError: name 'testpoint_id' is not defined
2021-05-01 17:59:23,858 INFO: InstroCommTool [in /home/michael/Projects/InstroCommTool/app/__init__.py:83
2021-05-01 17:59:33,977 ERROR: Exception on /update_testpoint [POST] [in /home/michael/Projects/InstroCommTool/venv/lib/python3.8/site-packages/flask/app.py:1891
Traceback (most recent call last):
  File "/home/michael/Projects/InstroCommTool/venv/lib/python3.8/site-packages/flask/app.py", line 2447, in wsgi_app
    response = self.full_dispatch_request()
  File "/home/michael/Projects/InstroCommTool/venv/lib/python3.8/site-packages/flask/app.py", line 1953, in full_dispatch_request
    return self.finalize_request(rv)
  File "/home/michael/Projects/InstroCommTool/venv/lib/python3.8/site-packages/flask/app.py", line 1968, in finalize_request
    response = self.make_response(rv)
  File "/home/michael/Projects/InstroCommTool/venv/lib/python3.8/site-packages/flask/app.py", line 2097, in make_response
    raise TypeError(
TypeError: The view function did not return a valid response. The function either returned None or ended without a return statement.
2021-05-02 15:09:12,082 INFO: InstroCommTool [in /home/michael/Projects/InstroCommTool/app/__init__.py:83
2021-05-02 15:09:50,441 ERROR: Exception on /update_testpoint [POST] [in /home/michael/Projects/InstroCommTool/venv/lib/python3.8/site-packages/flask/app.py:1891
Traceback (most recent call last):
  File "/home/michael/Projects/InstroCommTool/venv/lib/python3.8/site-packages/flask/app.py", line 2447, in wsgi_app
    response = self.full_dispatch_request()
  File "/home/michael/Projects/InstroCommTool/venv/lib/python3.8/site-packages/flask/app.py", line 1952, in full_dispatch_request
    rv = self.handle_user_exception(e)
  File "/home/michael/Projects/InstroCommTool/venv/lib/python3.8/site-packages/flask/app.py", line 1821, in handle_user_exception
    reraise(exc_type, exc_value, tb)
  File "/home/michael/Projects/InstroCommTool/venv/lib/python3.8/site-packages/flask/_compat.py", line 39, in reraise
    raise value
  File "/home/michael/Projects/InstroCommTool/venv/lib/python3.8/site-packages/flask/app.py", line 1950, in full_dispatch_request
    rv = self.dispatch_request()
  File "/home/michael/Projects/InstroCommTool/venv/lib/python3.8/site-packages/flask/app.py", line 1936, in dispatch_request
    return self.view_functions[rule.endpoint](**req.view_args)
  File "/home/michael/Projects/InstroCommTool/app/main/routes.py", line 156, in update_testpoint
    testpoint = Testpoint.query.filter_by(id=id)
NameError: name 'Testpoint' is not defined
2021-05-02 15:11:02,826 INFO: InstroCommTool [in /home/michael/Projects/InstroCommTool/app/__init__.py:83
2021-05-02 15:11:17,625 ERROR: Exception on /update_testpoint [POST] [in /home/michael/Projects/InstroCommTool/venv/lib/python3.8/site-packages/flask/app.py:1891
Traceback (most recent call last):
  File "/home/michael/Projects/InstroCommTool/venv/lib/python3.8/site-packages/flask/app.py", line 2447, in wsgi_app
    response = self.full_dispatch_request()
  File "/home/michael/Projects/InstroCommTool/venv/lib/python3.8/site-packages/flask/app.py", line 1952, in full_dispatch_request
    rv = self.handle_user_exception(e)
  File "/home/michael/Projects/InstroCommTool/venv/lib/python3.8/site-packages/flask/app.py", line 1821, in handle_user_exception
    reraise(exc_type, exc_value, tb)
  File "/home/michael/Projects/InstroCommTool/venv/lib/python3.8/site-packages/flask/_compat.py", line 39, in reraise
    raise value
  File "/home/michael/Projects/InstroCommTool/venv/lib/python3.8/site-packages/flask/app.py", line 1950, in full_dispatch_request
    rv = self.dispatch_request()
  File "/home/michael/Projects/InstroCommTool/venv/lib/python3.8/site-packages/flask/app.py", line 1936, in dispatch_request
    return self.view_functions[rule.endpoint](**req.view_args)
  File "/home/michael/Projects/InstroCommTool/app/main/routes.py", line 156, in update_testpoint
    testpoint = Testpoint.query.filter_by(id=id)
NameError: name 'Testpoint' is not defined
2021-05-02 15:12:46,845 INFO: InstroCommTool [in /home/michael/Projects/InstroCommTool/app/__init__.py:83
