2021-03-07 21:28:10,723 ERROR: Exception on /add_channel [POST] [in /home/michael/Projects/InstroCommTool/venv/lib/python3.8/site-packages/flask/app.py:1891
Traceback (most recent call last):
  File "/home/michael/Projects/InstroCommTool/venv/lib/python3.8/site-packages/sqlalchemy/engine/base.py", line 1204, in _execute_context
    context = constructor(dialect, self, conn, *args)
  File "/home/michael/Projects/InstroCommTool/venv/lib/python3.8/site-packages/sqlalchemy/engine/default.py", line 854, in _init_compiled
    param.append(processors[key](compiled_params[key]))
  File "/home/michael/Projects/InstroCommTool/venv/lib/python3.8/site-packages/sqlalchemy/dialects/sqlite/base.py", line 791, in process
    raise TypeError(
TypeError: SQLite DateTime type only accepts Python datetime and date objects as input.

The above exception was the direct cause of the following exception:

Traceback (most recent call last):
  File "/home/michael/Projects/InstroCommTool/venv/lib/python3.8/site-packages/flask/app.py", line 2447, in wsgi_app
    response = self.full_dispatch_request()
  File "/home/michael/Projects/InstroCommTool/venv/lib/python3.8/site-packages/flask/app.py", line 1952, in full_dispatch_request
    rv = self.handle_user_exception(e)
  File "/home/michael/Projects/InstroCommTool/venv/lib/python3.8/site-packages/flask/app.py", line 1821, in handle_user_exception
    reraise(exc_type, exc_value, tb)
  File "/home/michael/Projects/InstroCommTool/venv/lib/python3.8/site-packages/flask/_compat.py", line 39, in reraise
    raise value
  File "/home/michael/Projects/InstroCommTool/venv/lib/python3.8/site-packages/flask/app.py", line 1950, in full_dispatch_request
    rv = self.dispatch_request()
  File "/home/michael/Projects/InstroCommTool/venv/lib/python3.8/site-packages/flask/app.py", line 1936, in dispatch_request
    return self.view_functions[rule.endpoint](**req.view_args)
  File "/home/michael/Projects/InstroCommTool/app/main/routes.py", line 128, in add_channel
    db.session.commit()
  File "/home/michael/Projects/InstroCommTool/venv/lib/python3.8/site-packages/sqlalchemy/orm/scoping.py", line 163, in do
    return getattr(self.registry(), name)(*args, **kwargs)
  File "/home/michael/Projects/InstroCommTool/venv/lib/python3.8/site-packages/sqlalchemy/orm/session.py", line 1046, in commit
    self.transaction.commit()
  File "/home/michael/Projects/InstroCommTool/venv/lib/python3.8/site-packages/sqlalchemy/orm/session.py", line 504, in commit
    self._prepare_impl()
  File "/home/michael/Projects/InstroCommTool/venv/lib/python3.8/site-packages/sqlalchemy/orm/session.py", line 483, in _prepare_impl
    self.session.flush()
  File "/home/michael/Projects/InstroCommTool/venv/lib/python3.8/site-packages/sqlalchemy/orm/session.py", line 2540, in flush
    self._flush(objects)
  File "/home/michael/Projects/InstroCommTool/venv/lib/python3.8/site-packages/sqlalchemy/orm/session.py", line 2682, in _flush
    transaction.rollback(_capture_exception=True)
  File "/home/michael/Projects/InstroCommTool/venv/lib/python3.8/site-packages/sqlalchemy/util/langhelpers.py", line 68, in __exit__
    compat.raise_(
  File "/home/michael/Projects/InstroCommTool/venv/lib/python3.8/site-packages/sqlalchemy/util/compat.py", line 182, in raise_
    raise exception
  File "/home/michael/Projects/InstroCommTool/venv/lib/python3.8/site-packages/sqlalchemy/orm/session.py", line 2642, in _flush
    flush_context.execute()
  File "/home/michael/Projects/InstroCommTool/venv/lib/python3.8/site-packages/sqlalchemy/orm/unitofwork.py", line 422, in execute
    rec.execute(self)
  File "/home/michael/Projects/InstroCommTool/venv/lib/python3.8/site-packages/sqlalchemy/orm/unitofwork.py", line 586, in execute
    persistence.save_obj(
  File "/home/michael/Projects/InstroCommTool/venv/lib/python3.8/site-packages/sqlalchemy/orm/persistence.py", line 239, in save_obj
    _emit_insert_statements(
  File "/home/michael/Projects/InstroCommTool/venv/lib/python3.8/site-packages/sqlalchemy/orm/persistence.py", line 1135, in _emit_insert_statements
    result = cached_connections[connection].execute(
  File "/home/michael/Projects/InstroCommTool/venv/lib/python3.8/site-packages/sqlalchemy/engine/base.py", line 1011, in execute
    return meth(self, multiparams, params)
  File "/home/michael/Projects/InstroCommTool/venv/lib/python3.8/site-packages/sqlalchemy/sql/elements.py", line 298, in _execute_on_connection
    return connection._execute_clauseelement(self, multiparams, params)
  File "/home/michael/Projects/InstroCommTool/venv/lib/python3.8/site-packages/sqlalchemy/engine/base.py", line 1124, in _execute_clauseelement
    ret = self._execute_context(
  File "/home/michael/Projects/InstroCommTool/venv/lib/python3.8/site-packages/sqlalchemy/engine/base.py", line 1206, in _execute_context
    self._handle_dbapi_exception(
  File "/home/michael/Projects/InstroCommTool/venv/lib/python3.8/site-packages/sqlalchemy/engine/base.py", line 1510, in _handle_dbapi_exception
    util.raise_(
  File "/home/michael/Projects/InstroCommTool/venv/lib/python3.8/site-packages/sqlalchemy/util/compat.py", line 182, in raise_
    raise exception
  File "/home/michael/Projects/InstroCommTool/venv/lib/python3.8/site-packages/sqlalchemy/engine/base.py", line 1204, in _execute_context
    context = constructor(dialect, self, conn, *args)
  File "/home/michael/Projects/InstroCommTool/venv/lib/python3.8/site-packages/sqlalchemy/engine/default.py", line 854, in _init_compiled
    param.append(processors[key](compiled_params[key]))
  File "/home/michael/Projects/InstroCommTool/venv/lib/python3.8/site-packages/sqlalchemy/dialects/sqlite/base.py", line 791, in process
    raise TypeError(
sqlalchemy.exc.StatementError: (builtins.TypeError) SQLite DateTime type only accepts Python datetime and date objects as input.
[SQL: INSERT INTO test_point (channel_id, input_val, measured_val, nominal_val, pf, date_performed, notes) VALUES (?, ?, ?, ?, ?, ?, ?)]
[parameters: [{'pf': 2, 'notes': 'None', 'input_val': -50.0, 'measured_val': -20.0, 'nominal_val': -20.0, 'channel_id': 2, 'date_performed': <built-in method utcnow of type object at 0x92ab80>}]]
2021-03-07 21:32:25,537 INFO: InstroCommTool [in /home/michael/Projects/InstroCommTool/app/__init__.py:83
2021-03-07 21:34:10,958 INFO: InstroCommTool [in /home/michael/Projects/InstroCommTool/app/__init__.py:83
2021-03-07 21:47:45,096 INFO: InstroCommTool [in /home/michael/Projects/InstroCommTool/app/__init__.py:83
2021-03-07 21:47:47,611 ERROR: Exception on /index [GET] [in /home/michael/Projects/InstroCommTool/venv/lib/python3.8/site-packages/flask/app.py:1891
Traceback (most recent call last):
  File "/home/michael/Projects/InstroCommTool/venv/lib/python3.8/site-packages/flask/app.py", line 2447, in wsgi_app
    response = self.full_dispatch_request()
  File "/home/michael/Projects/InstroCommTool/venv/lib/python3.8/site-packages/flask/app.py", line 1952, in full_dispatch_request
    rv = self.handle_user_exception(e)
  File "/home/michael/Projects/InstroCommTool/venv/lib/python3.8/site-packages/flask/app.py", line 1821, in handle_user_exception
    reraise(exc_type, exc_value, tb)
  File "/home/michael/Projects/InstroCommTool/venv/lib/python3.8/site-packages/flask/_compat.py", line 39, in reraise
    raise value
  File "/home/michael/Projects/InstroCommTool/venv/lib/python3.8/site-packages/flask/app.py", line 1950, in full_dispatch_request
    rv = self.dispatch_request()
  File "/home/michael/Projects/InstroCommTool/venv/lib/python3.8/site-packages/flask/app.py", line 1936, in dispatch_request
    return self.view_functions[rule.endpoint](**req.view_args)
  File "/home/michael/Projects/InstroCommTool/app/main/routes.py", line 59, in index
    return render_template('index.html', title='Home', channels=channels, testpoints=testpoints)
  File "/home/michael/Projects/InstroCommTool/venv/lib/python3.8/site-packages/flask/templating.py", line 137, in render_template
    return _render(
  File "/home/michael/Projects/InstroCommTool/venv/lib/python3.8/site-packages/flask/templating.py", line 120, in _render
    rv = template.render(context)
  File "/home/michael/Projects/InstroCommTool/venv/lib/python3.8/site-packages/jinja2/environment.py", line 1090, in render
    self.environment.handle_exception()
  File "/home/michael/Projects/InstroCommTool/venv/lib/python3.8/site-packages/jinja2/environment.py", line 832, in handle_exception
    reraise(*rewrite_traceback_stack(source=source))
  File "/home/michael/Projects/InstroCommTool/venv/lib/python3.8/site-packages/jinja2/_compat.py", line 28, in reraise
    raise value.with_traceback(tb)
  File "/home/michael/Projects/InstroCommTool/app/templates/index.html", line 2, in top-level template code
    {% import 'bootstrap/wtf.html' as wtf %}
  File "/home/michael/Projects/InstroCommTool/app/templates/base.html", line 1, in top-level template code
    {% extends 'bootstrap/base.html' %}
  File "/home/michael/Projects/InstroCommTool/venv/lib/python3.8/site-packages/flask_bootstrap/templates/bootstrap/base.html", line 1, in top-level template code
    {% block doc -%}
  File "/home/michael/Projects/InstroCommTool/venv/lib/python3.8/site-packages/flask_bootstrap/templates/bootstrap/base.html", line 4, in block "doc"
    {%- block html %}
  File "/home/michael/Projects/InstroCommTool/venv/lib/python3.8/site-packages/flask_bootstrap/templates/bootstrap/base.html", line 20, in block "html"
    {% block body -%}
  File "/home/michael/Projects/InstroCommTool/venv/lib/python3.8/site-packages/flask_bootstrap/templates/bootstrap/base.html", line 23, in block "body"
    {% block content -%}
  File "/home/michael/Projects/InstroCommTool/app/templates/base.html", line 39, in block "content"
    {% block app_content %}{% endblock %}
  File "/home/michael/Projects/InstroCommTool/app/templates/index.html", line 11, in block "app_content"
    {% include '_channel.html' %}
  File "/home/michael/Projects/InstroCommTool/app/templates/_channel.html", line 17, in top-level template code
    {% for testpoint in testpoints %}
TypeError: 'TestPoint' object is not iterable
