2021-04-24 20:24:51,485 ERROR: Exception on /channel_list [GET] [in /home/michael/Projects/InstroCommTool/venv/lib/python3.8/site-packages/flask/app.py:1891
Traceback (most recent call last):
  File "/home/michael/Projects/InstroCommTool/venv/lib/python3.8/site-packages/flask/app.py", line 2447, in wsgi_app
    response = self.full_dispatch_request()
  File "/home/michael/Projects/InstroCommTool/venv/lib/python3.8/site-packages/flask/app.py", line 1952, in full_dispatch_request
    rv = self.handle_user_exception(e)
  File "/home/michael/Projects/InstroCommTool/venv/lib/python3.8/site-packages/flask/app.py", line 1821, in handle_user_exception
    reraise(exc_type, exc_value, tb)
  File "/home/michael/Projects/InstroCommTool/venv/lib/python3.8/site-packages/flask/_compat.py", line 39, in reraise
    raise value
  File "/home/michael/Projects/InstroCommTool/venv/lib/python3.8/site-packages/flask/app.py", line 1950, in full_dispatch_request
    rv = self.dispatch_request()
  File "/home/michael/Projects/InstroCommTool/venv/lib/python3.8/site-packages/flask/app.py", line 1936, in dispatch_request
    return self.view_functions[rule.endpoint](**req.view_args)
  File "/home/michael/Projects/InstroCommTool/app/main/routes.py", line 170, in channel_list
    print(testpoint_item.__iter__)
AttributeError: 'TestPointItem' object has no attribute '__iter__'
2021-04-24 20:26:51,144 INFO: InstroCommTool [in /home/michael/Projects/InstroCommTool/app/__init__.py:83
2021-04-24 20:26:53,179 ERROR: Exception on /channel_list [GET] [in /home/michael/Projects/InstroCommTool/venv/lib/python3.8/site-packages/flask/app.py:1891
Traceback (most recent call last):
  File "/home/michael/Projects/InstroCommTool/venv/lib/python3.8/site-packages/flask/app.py", line 2447, in wsgi_app
    response = self.full_dispatch_request()
  File "/home/michael/Projects/InstroCommTool/venv/lib/python3.8/site-packages/flask/app.py", line 1952, in full_dispatch_request
    rv = self.handle_user_exception(e)
  File "/home/michael/Projects/InstroCommTool/venv/lib/python3.8/site-packages/flask/app.py", line 1821, in handle_user_exception
    reraise(exc_type, exc_value, tb)
  File "/home/michael/Projects/InstroCommTool/venv/lib/python3.8/site-packages/flask/_compat.py", line 39, in reraise
    raise value
  File "/home/michael/Projects/InstroCommTool/venv/lib/python3.8/site-packages/flask/app.py", line 1950, in full_dispatch_request
    rv = self.dispatch_request()
  File "/home/michael/Projects/InstroCommTool/venv/lib/python3.8/site-packages/flask/app.py", line 1936, in dispatch_request
    return self.view_functions[rule.endpoint](**req.view_args)
  File "/home/michael/Projects/InstroCommTool/app/main/routes.py", line 172, in channel_list
    print(channel_item.channel_form.input_val)
AttributeError: 'ChannelForm' object has no attribute 'input_val'
2021-04-24 20:27:48,597 INFO: InstroCommTool [in /home/michael/Projects/InstroCommTool/app/__init__.py:83
2021-04-24 20:27:50,371 ERROR: Exception on /channel_list [GET] [in /home/michael/Projects/InstroCommTool/venv/lib/python3.8/site-packages/flask/app.py:1891
Traceback (most recent call last):
  File "/home/michael/Projects/InstroCommTool/venv/lib/python3.8/site-packages/flask/app.py", line 2447, in wsgi_app
    response = self.full_dispatch_request()
  File "/home/michael/Projects/InstroCommTool/venv/lib/python3.8/site-packages/flask/app.py", line 1952, in full_dispatch_request
    rv = self.handle_user_exception(e)
  File "/home/michael/Projects/InstroCommTool/venv/lib/python3.8/site-packages/flask/app.py", line 1821, in handle_user_exception
    reraise(exc_type, exc_value, tb)
  File "/home/michael/Projects/InstroCommTool/venv/lib/python3.8/site-packages/flask/_compat.py", line 39, in reraise
    raise value
  File "/home/michael/Projects/InstroCommTool/venv/lib/python3.8/site-packages/flask/app.py", line 1950, in full_dispatch_request
    rv = self.dispatch_request()
  File "/home/michael/Projects/InstroCommTool/venv/lib/python3.8/site-packages/flask/app.py", line 1936, in dispatch_request
    return self.view_functions[rule.endpoint](**req.view_args)
  File "/home/michael/Projects/InstroCommTool/app/main/routes.py", line 172, in channel_list
    print(channel_item.channel_form.testpoints.input_val)
AttributeError: 'FieldList' object has no attribute 'input_val'
2021-04-24 20:28:25,159 INFO: InstroCommTool [in /home/michael/Projects/InstroCommTool/app/__init__.py:83
2021-04-24 20:28:26,846 ERROR: Exception on /channel_list [GET] [in /home/michael/Projects/InstroCommTool/venv/lib/python3.8/site-packages/flask/app.py:1891
Traceback (most recent call last):
  File "/home/michael/Projects/InstroCommTool/venv/lib/python3.8/site-packages/flask/app.py", line 2447, in wsgi_app
    response = self.full_dispatch_request()
  File "/home/michael/Projects/InstroCommTool/venv/lib/python3.8/site-packages/flask/app.py", line 1952, in full_dispatch_request
    rv = self.handle_user_exception(e)
  File "/home/michael/Projects/InstroCommTool/venv/lib/python3.8/site-packages/flask/app.py", line 1821, in handle_user_exception
    reraise(exc_type, exc_value, tb)
  File "/home/michael/Projects/InstroCommTool/venv/lib/python3.8/site-packages/flask/_compat.py", line 39, in reraise
    raise value
  File "/home/michael/Projects/InstroCommTool/venv/lib/python3.8/site-packages/flask/app.py", line 1950, in full_dispatch_request
    rv = self.dispatch_request()
  File "/home/michael/Projects/InstroCommTool/venv/lib/python3.8/site-packages/flask/app.py", line 1936, in dispatch_request
    return self.view_functions[rule.endpoint](**req.view_args)
  File "/home/michael/Projects/InstroCommTool/app/main/routes.py", line 171, in channel_list
    print(channel_item.channel_form.testpoints.input_val)
AttributeError: 'FieldList' object has no attribute 'input_val'
2021-04-24 20:40:14,903 INFO: InstroCommTool [in /home/michael/Projects/InstroCommTool/app/__init__.py:83
2021-04-24 20:40:16,235 ERROR: Exception on /channel_list [GET] [in /home/michael/Projects/InstroCommTool/venv/lib/python3.8/site-packages/flask/app.py:1891
Traceback (most recent call last):
  File "/home/michael/Projects/InstroCommTool/venv/lib/python3.8/site-packages/flask/app.py", line 2447, in wsgi_app
    response = self.full_dispatch_request()
  File "/home/michael/Projects/InstroCommTool/venv/lib/python3.8/site-packages/flask/app.py", line 1952, in full_dispatch_request
    rv = self.handle_user_exception(e)
  File "/home/michael/Projects/InstroCommTool/venv/lib/python3.8/site-packages/flask/app.py", line 1821, in handle_user_exception
    reraise(exc_type, exc_value, tb)
  File "/home/michael/Projects/InstroCommTool/venv/lib/python3.8/site-packages/flask/_compat.py", line 39, in reraise
    raise value
  File "/home/michael/Projects/InstroCommTool/venv/lib/python3.8/site-packages/flask/app.py", line 1950, in full_dispatch_request
    rv = self.dispatch_request()
  File "/home/michael/Projects/InstroCommTool/venv/lib/python3.8/site-packages/flask/app.py", line 1936, in dispatch_request
    return self.view_functions[rule.endpoint](**req.view_args)
  File "/home/michael/Projects/InstroCommTool/app/main/routes.py", line 170, in channel_list
    print(channel_item.channel_form.testpoints.input_val)
AttributeError: 'FieldList' object has no attribute 'input_val'
2021-04-24 20:40:28,458 INFO: InstroCommTool [in /home/michael/Projects/InstroCommTool/app/__init__.py:83
